<?xml version="1.0" encoding="UTF-8"?>
<!-- Generated by org.testng.reporters.JUnitReportReporter -->
<testsuite skipped="2" hostname="DESKTOP-118273O" name="com.qa.hubspot.test.LoginPageTest" tests="10" failures="2" timestamp="2020-10-04T03:35:21 IST" time="183.549" errors="0">
  <testcase name="verifyTitleTest" time="29.210" classname="com.qa.hubspot.test.LoginPageTest">
    <failure type="java.lang.AssertionError" message="expected [HubSpot Login234] but found [HubSpot Login]">
      <![CDATA[java.lang.AssertionError: expected [HubSpot Login234] but found [HubSpot Login]
at org.testng.Assert.fail(Assert.java:97)
at org.testng.Assert.assertEqualsImpl(Assert.java:136)
at org.testng.Assert.assertEquals(Assert.java:118)
at org.testng.Assert.assertEquals(Assert.java:575)
at org.testng.Assert.assertEquals(Assert.java:585)
at com.qa.hubspot.test.LoginPageTest.verifyTitleTest(LoginPageTest.java:53)
at sun.reflect.NativeMethodAccessorImpl.invoke0(Native Method)
at sun.reflect.NativeMethodAccessorImpl.invoke(Unknown Source)
at sun.reflect.DelegatingMethodAccessorImpl.invoke(Unknown Source)
at java.lang.reflect.Method.invoke(Unknown Source)
at org.testng.internal.MethodInvocationHelper.invokeMethod(MethodInvocationHelper.java:135)
at org.testng.internal.TestInvoker.invokeMethod(TestInvoker.java:598)
at org.testng.internal.TestInvoker.invokeTestMethod(TestInvoker.java:174)
at org.testng.internal.MethodRunner.runInSequence(MethodRunner.java:46)
at org.testng.internal.TestInvoker$MethodInvocationAgent.invoke(TestInvoker.java:821)
at org.testng.internal.TestInvoker.invokeTestMethods(TestInvoker.java:147)
at org.testng.internal.TestMethodWorker.invokeTestMethods(TestMethodWorker.java:146)
at org.testng.internal.TestMethodWorker.run(TestMethodWorker.java:128)
at java.util.ArrayList.forEach(Unknown Source)
at org.testng.TestRunner.privateRun(TestRunner.java:767)
at org.testng.TestRunner.run(TestRunner.java:588)
at org.testng.SuiteRunner.runTest(SuiteRunner.java:384)
at org.testng.SuiteRunner.access$000(SuiteRunner.java:28)
at org.testng.SuiteRunner$SuiteWorker.run(SuiteRunner.java:425)
at org.testng.internal.thread.ThreadUtil.lambda$execute$0(ThreadUtil.java:68)
at java.util.concurrent.FutureTask.run(Unknown Source)
at java.util.concurrent.ThreadPoolExecutor.runWorker(Unknown Source)
at java.util.concurrent.ThreadPoolExecutor$Worker.run(Unknown Source)
at java.lang.Thread.run(Unknown Source)
]]>
    </failure>
  </testcase> <!-- verifyTitleTest -->
  <system-out/>
  <testcase name="verifyTitleTest" time="28.915" classname="com.qa.hubspot.test.LoginPageTest">
    <failure type="java.lang.AssertionError" message="expected [HubSpot Login234] but found [HubSpot Login]">
      <![CDATA[java.lang.AssertionError: expected [HubSpot Login234] but found [HubSpot Login]
at org.testng.Assert.fail(Assert.java:97)
at org.testng.Assert.assertEqualsImpl(Assert.java:136)
at org.testng.Assert.assertEquals(Assert.java:118)
at org.testng.Assert.assertEquals(Assert.java:575)
at org.testng.Assert.assertEquals(Assert.java:585)
at com.qa.hubspot.test.LoginPageTest.verifyTitleTest(LoginPageTest.java:53)
at sun.reflect.NativeMethodAccessorImpl.invoke0(Native Method)
at sun.reflect.NativeMethodAccessorImpl.invoke(Unknown Source)
at sun.reflect.DelegatingMethodAccessorImpl.invoke(Unknown Source)
at java.lang.reflect.Method.invoke(Unknown Source)
at org.testng.internal.MethodInvocationHelper.invokeMethod(MethodInvocationHelper.java:135)
at org.testng.internal.TestInvoker.invokeMethod(TestInvoker.java:598)
at org.testng.internal.TestInvoker.invokeTestMethod(TestInvoker.java:174)
at org.testng.internal.MethodRunner.runInSequence(MethodRunner.java:46)
at org.testng.internal.TestInvoker$MethodInvocationAgent.invoke(TestInvoker.java:821)
at org.testng.internal.TestInvoker.invokeTestMethods(TestInvoker.java:147)
at org.testng.internal.TestMethodWorker.invokeTestMethods(TestMethodWorker.java:146)
at org.testng.internal.TestMethodWorker.run(TestMethodWorker.java:128)
at java.util.ArrayList.forEach(Unknown Source)
at org.testng.TestRunner.privateRun(TestRunner.java:767)
at org.testng.TestRunner.run(TestRunner.java:588)
at org.testng.SuiteRunner.runTest(SuiteRunner.java:384)
at org.testng.SuiteRunner.access$000(SuiteRunner.java:28)
at org.testng.SuiteRunner$SuiteWorker.run(SuiteRunner.java:425)
at org.testng.internal.thread.ThreadUtil.lambda$execute$0(ThreadUtil.java:68)
at java.util.concurrent.FutureTask.run(Unknown Source)
at java.util.concurrent.ThreadPoolExecutor.runWorker(Unknown Source)
at java.util.concurrent.ThreadPoolExecutor$Worker.run(Unknown Source)
at java.lang.Thread.run(Unknown Source)
]]>
    </failure>
  </testcase> <!-- verifyTitleTest -->
  <system-out/>
  <testcase name="verifySignupTest" time="23.842" classname="com.qa.hubspot.test.LoginPageTest"/>
  <system-out/>
  <testcase name="verifySignupTest" time="17.806" classname="com.qa.hubspot.test.LoginPageTest"/>
  <system-out/>
  <testcase name="verifyForgotPasswordTest" time="22.575" classname="com.qa.hubspot.test.LoginPageTest"/>
  <system-out/>
  <testcase name="verifyForgotPasswordTest" time="18.714" classname="com.qa.hubspot.test.LoginPageTest"/>
  <system-out/>
  <testcase name="verifyLoginTest" time="17.448" classname="com.qa.hubspot.test.LoginPageTest"/>
  <system-out/>
  <testcase name="verifyLoginTest" time="25.039" classname="com.qa.hubspot.test.LoginPageTest"/>
  <system-out/>
  <testcase name="negativeLoginTest" classname="com.qa.hubspot.test.LoginPageTest">
    <skipped/>
  </testcase> <!-- negativeLoginTest -->
  <system-out/>
  <testcase name="negativeLoginTest" classname="com.qa.hubspot.test.LoginPageTest">
    <skipped/>
  </testcase> <!-- negativeLoginTest -->
  <system-out/>
</testsuite> <!-- com.qa.hubspot.test.LoginPageTest -->
